Workbook

Sheet summary
C1: Gastos individuales de cada uno | E1: Cuánto aportó cada uno a los gastos compartidos | H1: % aportado del total de compartidos | J1: cuánto desembolsó cada uno de su bolsillo | L1: cuánto ingresó cada uno marcado como individual | N1: cuánto ingresó cada uno marcado como compartido | P1: % de ingresos compartidos aportados | S1: cuánto ingresó cada uno total (tanto marcado individual como compartido) | U1: ahorro en el bolsillo x persona (ingresos de una persona - gastos compartidos divididos proporcionalmente - gastos individuales) | W1: ahorro servicios | AA1: cuánto le debe uno a otro para balancear los gastos compartidos mensuales | AC1: neto ahorro hogar
B2: Gastos por mes | C2: gastos (ind) | D2: gastos (ind) | E2: gastos compartidos | F2: gastos compartidos | G2: gastos compartidos | H2: gastos compartidos % | I2: gastos compartidos % | J2: gastos total (comp + ind) | K2: gastos total (comp + ind) | L2: ingresos (ind) | M2: ingresos (ind) | N2: ingresos compartidos | O2: ingresos compartidos | P2: ingresos % | Q2: ingresos % | R2: ingresos compartidos | S2: ingresos total (comp + ind) | T2: ingresos total (comp + ind) | U2: ahorro (comp - ind) | V2: ahorro (comp - ind) | W2: ahorro (compartido) | X2: % ahorro sobre ingreso x persona | Y2: % ahorro sobre ingreso x persona | Z2: % ahorro (compartido) | AA2: saldo
B3: user | C3: user-a | D3: user-b | E3: user-a | F3: user-b | G3: total | H3: user-a | I3: user-b | J3: user-a | K3: user-b | L3: user-a | M3: user-b | N3: user-a | O3: user-b | P3: user-a | Q3: user-b | R3: total | S3: user-a | T3: user-b | U3: user-a | V3: user-b | W3: total | X3: user-a | Y3: user-b | Z3: total | AA3: user-a a user-b | AB3: user-b a user-a
A4: =YEAR(B4) -> 2024 | B4: 45444 | C4: =SUMIFS( expenses_by_installments!$L:$L, expenses_by_installments!$I:$I, "Egreso", expenses_by_installments!$K:$K, C$3, expenses_by_installments!$J:$J, "No", expenses_by_installments!$B:$B, ">="&$B4, expenses_by_installments!$B:$B, "<="&EOMONTH($B4, 0) ) -> 0 | D4: =SUMIFS( expenses_by_installments!$L:$L, expenses_by_installments!$I:$I, "Egreso", expenses_by_installments!$K:$K, D$3, expenses_by_installments!$J:$J, "No", expenses_by_installments!$B:$B, ">="&$B4, expenses_by_installments!$B:$B, "<="&EOMONTH($B4, 0) ) -> 209.03285 | E4: =SUMIFS( expenses_by_installments!$L:$L, expenses_by_installments!$I:$I, "Egreso", expenses_by_installments!$J:$J, "Si", expenses_by_installments!$K:$K, E$3, expenses_by_installments!$B:$B, ">="&$B4, expenses_by_installments!$B:$B, "<="&EOMONTH($B4, 0) ) -> 0 | F4: =SUMIFS( expenses_by_installments!$L:$L, expenses_by_installments!$I:$I, "Egreso", expenses_by_installments!$J:$J, "Si", expenses_by_installments!$K:$K, F$3, expenses_by_installments!$B:$B, ">="&$B4, expenses_by_installments!$B:$B, "<="&EOMONTH($B4, 0) ) -> 795.59854 | G4: =E4+F4 -> 795.59854 | H4: =E4/$G4 -> 0 | I4: =F4/$G4 -> 1 | J4: =E4+C4 -> 0 | K4: =F4+D4 -> 1004.6314 | L4: =SUMIFS( expenses_by_installments!$L:$L, expenses_by_installments!$I:$I, "Ingreso", expenses_by_installments!$K:$K, L$3, expenses_by_installments!$J:$J, "No", expenses_by_installments!$B:$B, ">="&$B4, expenses_by_installments!$B:$B, "<="&EOMONTH($B4, 0) ) -> 0 | M4: =SUMIFS( expenses_by_installments!$L:$L, expenses_by_installments!$I:$I, "Ingreso", expenses_by_installments!$K:$K, M$3, expenses_by_installments!$J:$J, "No", expenses_by_installments!$B:$B, ">="&$B4, expenses_by_installments!$B:$B, "<="&EOMONTH($B4, 0) ) -> 0 | N4: =SUMIFS( expenses_by_installments!$L:$L, expenses_by_installments!$I:$I, "Ingreso", expenses_by_installments!$K:$K, N$3, expenses_by_installments!$J:$J, "Si", expenses_by_installments!$B:$B, ">="&$B4, expenses_by_installments!$B:$B, "<="&EOMONTH($B4, 0) ) -> 0 | O4: 1500 | P4: 0 | Q4: 1 | R4: =N4+O4 -> 1500 | S4: =L4+N4 -> 0 | T4: =M4+O4 -> 1500 | U4: =(S4) - C4 - (G4 * P4) -> 0 | V4: =T4 - D4 - (Q4 * G4) -> 495.36861 | W4: =R4-G4 -> 704.40146 | X4: =U4/S4 -> #DIV/0! | Y4: =V4/T4 -> 0.33024574 | Z4: =W4/R4 -> 0.46960097 | AA4: =MAX(0, (P4 * G4) - E4) -> 0 | AB4: =MAX(0, (Q4 * G4) - F4) -> 0 | AC4: =R4-K4-J4 -> 495.36861
A5: =YEAR(B5) -> 2024 | B5: 45474 | C5: =SUMIFS( expenses_by_installments!$L:$L, expenses_by_installments!$I:$I, "Egreso", expenses_by_installments!$K:$K, C$3, expenses_by_installments!$J:$J, "No", expenses_by_installments!$B:$B, ">="&$B5, expenses_by_installments!$B:$B, "<="&EOMONTH($B5, 0) ) -> 0 | D5: =SUMIFS( expenses_by_installments!$L:$L, expenses_by_installments!$I:$I, "Egreso", expenses_by_installments!$K:$K, D$3, expenses_by_installments!$J:$J, "No", expenses_by_installments!$B:$B, ">="&$B5, expenses_by_installments!$B:$B, "<="&EOMONTH($B5, 0) ) -> 80.946154 | E5: =SUMIFS( expenses_by_installments!$L:$L, expenses_by_installments!$I:$I, "Egreso", expenses_by_installments!$J:$J, "Si", expenses_by_installments!$K:$K, E$3, expenses_by_installments!$B:$B, ">="&$B5, expenses_by_installments!$B:$B, "<="&EOMONTH($B5, 0) ) -> 0 | F5: =SUMIFS( expenses_by_installments!$L:$L, expenses_by_installments!$I:$I, "Egreso", expenses_by_installments!$J:$J, "Si", expenses_by_installments!$K:$K, F$3, expenses_by_installments!$B:$B, ">="&$B5, expenses_by_installments!$B:$B, "<="&EOMONTH($B5, 0) ) -> 967.16154 | G5: =E5+F5 -> 967.16154 | H5: =E5/$G5 -> 0 | I5: =F5/$G5 -> 1 | J5: =E5+C5 -> 0 | K5: =F5+D5 -> 1048.1077 | L5: =SUMIFS( expenses_by_installments!$L:$L, expenses_by_installments!$I:$I, "Ingreso", expenses_by_installments!$K:$K, L$3, expenses_by_installments!$J:$J, "No", expenses_by_installments!$B:$B, ">="&$B5, expenses_by_installments!$B:$B, "<="&EOMONTH($B5, 0) ) -> 0 | M5: =SUMIFS( expenses_by_installments!$L:$L, expenses_by_installments!$I:$I, "Ingreso", expenses_by_installments!$K:$K, M$3, expenses_by_installments!$J:$J, "No", expenses_by_installments!$B:$B, ">="&$B5, expenses_by_installments!$B:$B, "<="&EOMONTH($B5, 0) ) -> 0 | N5: =SUMIFS( expenses_by_installments!$L:$L, expenses_by_installments!$I:$I, "Ingreso", expenses_by_installments!$K:$K, N$3, expenses_by_installments!$J:$J, "Si", expenses_by_installments!$B:$B, ">="&$B5, expenses_by_installments!$B:$B, "<="&EOMONTH($B5, 0) ) -> 0 | O5: 1500 | P5: 0 | Q5: 1 | R5: =N5+O5 -> 1500 | S5: =L5+N5 -> 0 | T5: =M5+O5 -> 1500 | U5: =(S5) - C5 - (G5 * P5) -> 0 | V5: =T5 - D5 - (Q5 * G5) -> 451.89231 | W5: =R5-G5 -> 532.83846 | X5: =U5/S5 -> #DIV/0! | Y5: =V5/T5 -> 0.30126154 | Z5: =W5/R5 -> 0.35522564 | AA5: =MAX(0, (P5 * G5) - E5) -> 0 | AB5: =MAX(0, (Q5 * G5) - F5) -> 0 | AC5: =R5-K5-J5 -> 451.89231
A6: =YEAR(B6) -> 2024 | B6: 45505 | C6: =SUMIFS( expenses_by_installments!$L:$L, expenses_by_installments!$I:$I, "Egreso", expenses_by_installments!$K:$K, C$3, expenses_by_installments!$J:$J, "No", expenses_by_installments!$B:$B, ">="&$B6, expenses_by_installments!$B:$B, "<="&EOMONTH($B6, 0) ) -> 0 | D6: =SUMIFS( expenses_by_installments!$L:$L, expenses_by_installments!$I:$I, "Egreso", expenses_by_installments!$K:$K, D$3, expenses_by_installments!$J:$J, "No", expenses_by_installments!$B:$B, ">="&$B6, expenses_by_installments!$B:$B, "<="&EOMONTH($B6, 0) ) -> 66.340081 | E6: =SUMIFS( expenses_by_installments!$L:$L, expenses_by_installments!$I:$I, "Egreso", expenses_by_installments!$J:$J, "Si", expenses_by_installments!$K:$K, E$3, expenses_by_installments!$B:$B, ">="&$B6, expenses_by_installments!$B:$B, "<="&EOMONTH($B6, 0) ) -> 0 | F6: =SUMIFS( expenses_by_installments!$L:$L, expenses_by_installments!$I:$I, "Egreso", expenses_by_installments!$J:$J, "Si", expenses_by_installments!$K:$K, F$3, expenses_by_installments!$B:$B, ">="&$B6, expenses_by_installments!$B:$B, "<="&EOMONTH($B6, 0) ) -> 140.21053 | G6: =E6+F6 -> 140.21053 | H6: =E6/$G6 -> 0 | I6: =F6/$G6 -> 1 | J6: =E6+C6 -> 0 | K6: =F6+D6 -> 206.55061 | L6: =SUMIFS( expenses_by_installments!$L:$L, expenses_by_installments!$I:$I, "Ingreso", expenses_by_installments!$K:$K, L$3, expenses_by_installments!$J:$J, "No", expenses_by_installments!$B:$B, ">="&$B6, expenses_by_installments!$B:$B, "<="&EOMONTH($B6, 0) ) -> 0 | M6: =SUMIFS( expenses_by_installments!$L:$L, expenses_by_installments!$I:$I, "Ingreso", expenses_by_installments!$K:$K, M$3, expenses_by_installments!$J:$J, "No", expenses_by_installments!$B:$B, ">="&$B6, expenses_by_installments!$B:$B, "<="&EOMONTH($B6, 0) ) -> 0 | N6: =SUMIFS( expenses_by_installments!$L:$L, expenses_by_installments!$I:$I, "Ingreso", expenses_by_installments!$K:$K, N$3, expenses_by_installments!$J:$J, "Si", expenses_by_installments!$B:$B, ">="&$B6, expenses_by_installments!$B:$B, "<="&EOMONTH($B6, 0) ) -> 0 | O6: =SUMIFS( expenses_by_installments!$L:$L, expenses_by_installments!$I:$I, "Ingreso", expenses_by_installments!$K:$K, O$3, expenses_by_installments!$J:$J, "Si", expenses_by_installments!$B:$B, ">="&$B6, expenses_by_installments!$B:$B, "<="&EOMONTH($B6, 0) ) -> 0 | P6: 0 | Q6: 1 | R6: =N6+O6 -> 0 | S6: =L6+N6 -> 0 | T6: =M6+O6 -> 0 | U6: =(S6) - C6 - (G6 * P6) -> 0 | V6: =T6 - D6 - (Q6 * G6) -> -206.55061 | W6: =R6-G6 -> -140.21053 | X6: =U6/S6 -> #DIV/0! | Y6: =V6/T6 -> #DIV/0! | Z6: =W6/R6 -> #DIV/0! | AA6: =MAX(0, (P6 * G6) - E6) -> 0 | AB6: =MAX(0, (Q6 * G6) - F6) -> 0 | AC6: =R6-K6-J6 -> -206.55061
A7: =YEAR(B7) -> 2024 | B7: 45536 | C7: =SUMIFS( expenses_by_installments!$L:$L, expenses_by_installments!$I:$I, "Egreso", expenses_by_installments!$K:$K, C$3, expenses_by_installments!$J:$J, "No", expenses_by_installments!$B:$B, ">="&$B7, expenses_by_installments!$B:$B, "<="&EOMONTH($B7, 0) ) -> 0 | D7: =SUMIFS( expenses_by_installments!$L:$L, expenses_by_installments!$I:$I, "Egreso", expenses_by_installments!$K:$K, D$3, expenses_by_installments!$J:$J, "No", expenses_by_installments!$B:$B, ">="&$B7, expenses_by_installments!$B:$B, "<="&EOMONTH($B7, 0) ) -> 45.123967 | E7: =SUMIFS( expenses_by_installments!$L:$L, expenses_by_installments!$I:$I, "Egreso", expenses_by_installments!$J:$J, "Si", expenses_by_installments!$K:$K, E$3, expenses_by_installments!$B:$B, ">="&$B7, expenses_by_installments!$B:$B, "<="&EOMONTH($B7, 0) ) -> 0 | F7: =SUMIFS( expenses_by_installments!$L:$L, expenses_by_installments!$I:$I, "Egreso", expenses_by_installments!$J:$J, "Si", expenses_by_installments!$K:$K, F$3, expenses_by_installments!$B:$B, ">="&$B7, expenses_by_installments!$B:$B, "<="&EOMONTH($B7, 0) ) -> 116.10744 | G7: =E7+F7 -> 116.10744 | H7: =E7/$G7 -> 0 | I7: =F7/$G7 -> 1 | J7: =E7+C7 -> 0 | K7: =F7+D7 -> 161.2314 | L7: =SUMIFS( expenses_by_installments!$L:$L, expenses_by_installments!$I:$I, "Ingreso", expenses_by_installments!$K:$K, L$3, expenses_by_installments!$J:$J, "No", expenses_by_installments!$B:$B, ">="&$B7, expenses_by_installments!$B:$B, "<="&EOMONTH($B7, 0) ) -> 0 | M7: =SUMIFS( expenses_by_installments!$L:$L, expenses_by_installments!$I:$I, "Ingreso", expenses_by_installments!$K:$K, M$3, expenses_by_installments!$J:$J, "No", expenses_by_installments!$B:$B, ">="&$B7, expenses_by_installments!$B:$B, "<="&EOMONTH($B7, 0) ) -> 0 | N7: =SUMIFS( expenses_by_installments!$L:$L, expenses_by_installments!$I:$I, "Ingreso", expenses_by_installments!$K:$K, N$3, expenses_by_installments!$J:$J, "Si", expenses_by_installments!$B:$B, ">="&$B7, expenses_by_installments!$B:$B, "<="&EOMONTH($B7, 0) ) -> 0 | O7: =SUMIFS( expenses_by_installments!$L:$L, expenses_by_installments!$I:$I, "Ingreso", expenses_by_installments!$K:$K, O$3, expenses_by_installments!$J:$J, "Si", expenses_by_installments!$B:$B, ">="&$B7, expenses_by_installments!$B:$B, "<="&EOMONTH($B7, 0) ) -> 0 | P7: 0 | Q7: 1 | R7: =N7+O7 -> 0 | S7: =L7+N7 -> 0 | T7: =M7+O7 -> 0 | U7: =(S7) - C7 - (G7 * P7) -> 0 | V7: =T7 - D7 - (Q7 * G7) -> -161.2314 | W7: =R7-G7 -> -116.10744 | X7: =U7/S7 -> #DIV/0! | Y7: =V7/T7 -> #DIV/0! | Z7: =W7/R7 -> #DIV/0! | AA7: =MAX(0, (P7 * G7) - E7) -> 0 | AB7: =MAX(0, (Q7 * G7) - F7) -> 0 | AC7: =R7-K7-J7 -> -161.2314
A8: =YEAR(B8) -> 2024 | B8: 45566 | C8: =SUMIFS( expenses_by_installments!$L:$L, expenses_by_installments!$I:$I, "Egreso", expenses_by_installments!$K:$K, C$3, expenses_by_installments!$J:$J, "No", expenses_by_installments!$B:$B, ">="&$B8, expenses_by_installments!$B:$B, "<="&EOMONTH($B8, 0) ) -> 0 | D8: =SUMIFS( expenses_by_installments!$L:$L, expenses_by_installments!$I:$I, "Egreso", expenses_by_installments!$K:$K, D$3, expenses_by_installments!$J:$J, "No", expenses_by_installments!$B:$B, ">="&$B8, expenses_by_installments!$B:$B, "<="&EOMONTH($B8, 0) ) -> 47.894737 | E8: =SUMIFS( expenses_by_installments!$L:$L, expenses_by_installments!$I:$I, "Egreso", expenses_by_installments!$J:$J, "Si", expenses_by_installments!$K:$K, E$3, expenses_by_installments!$B:$B, ">="&$B8, expenses_by_installments!$B:$B, "<="&EOMONTH($B8, 0) ) -> 0 | F8: =SUMIFS( expenses_by_installments!$L:$L, expenses_by_installments!$I:$I, "Egreso", expenses_by_installments!$J:$J, "Si", expenses_by_installments!$K:$K, F$3, expenses_by_installments!$B:$B, ">="&$B8, expenses_by_installments!$B:$B, "<="&EOMONTH($B8, 0) ) -> 28.438596 | G8: =E8+F8 -> 28.438596 | H8: =E8/$G8 -> 0 | I8: =F8/$G8 -> 1 | J8: =E8+C8 -> 0 | K8: =F8+D8 -> 76.333333 | L8: =SUMIFS( expenses_by_installments!$L:$L, expenses_by_installments!$I:$I, "Ingreso", expenses_by_installments!$K:$K, L$3, expenses_by_installments!$J:$J, "No", expenses_by_installments!$B:$B, ">="&$B8, expenses_by_installments!$B:$B, "<="&EOMONTH($B8, 0) ) -> 0 | M8: =SUMIFS( expenses_by_installments!$L:$L, expenses_by_installments!$I:$I, "Ingreso", expenses_by_installments!$K:$K, M$3, expenses_by_installments!$J:$J, "No", expenses_by_installments!$B:$B, ">="&$B8, expenses_by_installments!$B:$B, "<="&EOMONTH($B8, 0) ) -> 0 | N8: =SUMIFS( expenses_by_installments!$L:$L, expenses_by_installments!$I:$I, "Ingreso", expenses_by_installments!$K:$K, N$3, expenses_by_installments!$J:$J, "Si", expenses_by_installments!$B:$B, ">="&$B8, expenses_by_installments!$B:$B, "<="&EOMONTH($B8, 0) ) -> 0 | O8: =SUMIFS( expenses_by_installments!$L:$L, expenses_by_installments!$I:$I, "Ingreso", expenses_by_installments!$K:$K, O$3, expenses_by_installments!$J:$J, "Si", expenses_by_installments!$B:$B, ">="&$B8, expenses_by_installments!$B:$B, "<="&EOMONTH($B8, 0) ) -> 0 | P8: 0 | Q8: 1 | R8: =N8+O8 -> 0 | S8: =L8+N8 -> 0 | T8: =M8+O8 -> 0 | U8: =(S8) - C8 - (G8 * P8) -> 0 | V8: =T8 - D8 - (Q8 * G8) -> -76.333333 | W8: =R8-G8 -> -28.438596 | X8: =U8/S8 -> #DIV/0! | Y8: =V8/T8 -> #DIV/0! | Z8: =W8/R8 -> #DIV/0! | AA8: =MAX(0, (P8 * G8) - E8) -> 0 | AB8: =MAX(0, (Q8 * G8) - F8) -> 0 | AC8: =R8-K8-J8 -> -76.333333
A9: =YEAR(B9) -> 2024 | B9: 45597 | C9: =SUMIFS( expenses_by_installments!$L:$L, expenses_by_installments!$I:$I, "Egreso", expenses_by_installments!$K:$K, C$3, expenses_by_installments!$J:$J, "No", expenses_by_installments!$B:$B, ">="&$B8, expenses_by_installments!$B:$B, "<="&EOMONTH($B8, 0) ) -> 0 | D9: =SUMIFS( expenses_by_installments!$L:$L, expenses_by_installments!$I:$I, "Egreso", expenses_by_installments!$K:$K, D$3, expenses_by_installments!$J:$J, "No", expenses_by_installments!$B:$B, ">="&$B8, expenses_by_installments!$B:$B, "<="&EOMONTH($B8, 0) ) -> 47.894737 | E9: =SUMIFS( expenses_by_installments!$L:$L, expenses_by_installments!$I:$I, "Egreso", expenses_by_installments!$J:$J, "Si", expenses_by_installments!$K:$K, E$3, expenses_by_installments!$B:$B, ">="&$B8, expenses_by_installments!$B:$B, "<="&EOMONTH($B8, 0) ) -> 0 | F9: =SUMIFS( expenses_by_installments!$L:$L, expenses_by_installments!$I:$I, "Egreso", expenses_by_installments!$J:$J, "Si", expenses_by_installments!$K:$K, F$3, expenses_by_installments!$B:$B, ">="&$B8, expenses_by_installments!$B:$B, "<="&EOMONTH($B8, 0) ) -> 28.438596 | G9: =E8+F8 -> 28.438596 | H9: =E8/$G8 -> 0 | I9: =F8/$G8 -> 1 | J9: =E8+C8 -> 0 | K9: =F8+D8 -> 76.333333 | L9: =SUMIFS( expenses_by_installments!$L:$L, expenses_by_installments!$I:$I, "Ingreso", expenses_by_installments!$K:$K, L$3, expenses_by_installments!$J:$J, "No", expenses_by_installments!$B:$B, ">="&$B8, expenses_by_installments!$B:$B, "<="&EOMONTH($B8, 0) ) -> 0 | M9: =SUMIFS( expenses_by_installments!$L:$L, expenses_by_installments!$I:$I, "Ingreso", expenses_by_installments!$K:$K, M$3, expenses_by_installments!$J:$J, "No", expenses_by_installments!$B:$B, ">="&$B8, expenses_by_installments!$B:$B, "<="&EOMONTH($B8, 0) ) -> 0 | N9: =SUMIFS( expenses_by_installments!$L:$L, expenses_by_installments!$I:$I, "Ingreso", expenses_by_installments!$K:$K, N$3, expenses_by_installments!$J:$J, "Si", expenses_by_installments!$B:$B, ">="&$B8, expenses_by_installments!$B:$B, "<="&EOMONTH($B8, 0) ) -> 0 | O9: =SUMIFS( expenses_by_installments!$L:$L, expenses_by_installments!$I:$I, "Ingreso", expenses_by_installments!$K:$K, O$3, expenses_by_installments!$J:$J, "Si", expenses_by_installments!$B:$B, ">="&$B8, expenses_by_installments!$B:$B, "<="&EOMONTH($B8, 0) ) -> 0 | P9: 0 | Q9: 0 | R9: =N8+O8 -> 0 | S9: =L8+N8 -> 0 | T9: =M8+O8 -> 0 | U9: =(S8) - C8 - (G8 * P8) -> 0 | V9: =T8 - D8 - (Q8 * G8) -> -76.333333 | W9: =R8-G8 -> -28.438596 | X9: =U8/S8 -> #DIV/0! | Y9: =V8/T8 -> #DIV/0! | Z9: =W8/R8 -> #DIV/0! | AA9: =MAX(0, (P8 * G8) - E8) -> 0 | AB9: =MAX(0, (Q8 * G8) - F8) -> 0 | AC9: =R8-K8-J8 -> -76.333333
A10: =YEAR(B10) -> 2024 | B10: 45627 | C10: =SUMIFS( expenses_by_installments!$L:$L, expenses_by_installments!$I:$I, "Egreso", expenses_by_installments!$K:$K, C$3, expenses_by_installments!$J:$J, "No", expenses_by_installments!$B:$B, ">="&$B8, expenses_by_installments!$B:$B, "<="&EOMONTH($B8, 0) ) -> 0 | D10: =SUMIFS( expenses_by_installments!$L:$L, expenses_by_installments!$I:$I, "Egreso", expenses_by_installments!$K:$K, D$3, expenses_by_installments!$J:$J, "No", expenses_by_installments!$B:$B, ">="&$B8, expenses_by_installments!$B:$B, "<="&EOMONTH($B8, 0) ) -> 47.894737 | E10: =SUMIFS( expenses_by_installments!$L:$L, expenses_by_installments!$I:$I, "Egreso", expenses_by_installments!$J:$J, "Si", expenses_by_installments!$K:$K, E$3, expenses_by_installments!$B:$B, ">="&$B8, expenses_by_installments!$B:$B, "<="&EOMONTH($B8, 0) ) -> 0 | F10: =SUMIFS( expenses_by_installments!$L:$L, expenses_by_installments!$I:$I, "Egreso", expenses_by_installments!$J:$J, "Si", expenses_by_installments!$K:$K, F$3, expenses_by_installments!$B:$B, ">="&$B8, expenses_by_installments!$B:$B, "<="&EOMONTH($B8, 0) ) -> 28.438596 | G10: =E8+F8 -> 28.438596 | H10: =E8/$G8 -> 0 | I10: =F8/$G8 -> 1 | J10: =E8+C8 -> 0 | K10: =F8+D8 -> 76.333333 | L10: =SUMIFS( expenses_by_installments!$L:$L, expenses_by_installments!$I:$I, "Ingreso", expenses_by_installments!$K:$K, L$3, expenses_by_installments!$J:$J, "No", expenses_by_installments!$B:$B, ">="&$B8, expenses_by_installments!$B:$B, "<="&EOMONTH($B8, 0) ) -> 0 | M10: =SUMIFS( expenses_by_installments!$L:$L, expenses_by_installments!$I:$I, "Ingreso", expenses_by_installments!$K:$K, M$3, expenses_by_installments!$J:$J, "No", expenses_by_installments!$B:$B, ">="&$B8, expenses_by_installments!$B:$B, "<="&EOMONTH($B8, 0) ) -> 0 | N10: =SUMIFS( expenses_by_installments!$L:$L, expenses_by_installments!$I:$I, "Ingreso", expenses_by_installments!$K:$K, N$3, expenses_by_installments!$J:$J, "Si", expenses_by_installments!$B:$B, ">="&$B8, expenses_by_installments!$B:$B, "<="&EOMONTH($B8, 0) ) -> 0 | O10: =SUMIFS( expenses_by_installments!$L:$L, expenses_by_installments!$I:$I, "Ingreso", expenses_by_installments!$K:$K, O$3, expenses_by_installments!$J:$J, "Si", expenses_by_installments!$B:$B, ">="&$B8, expenses_by_installments!$B:$B, "<="&EOMONTH($B8, 0) ) -> 0 | P10: 0 | Q10: 0 | R10: =N8+O8 -> 0 | S10: =L8+N8 -> 0 | T10: =M8+O8 -> 0 | U10: =(S8) - C8 - (G8 * P8) -> 0 | V10: =T8 - D8 - (Q8 * G8) -> -76.333333 | W10: =R8-G8 -> -28.438596 | X10: =U8/S8 -> #DIV/0! | Y10: =V8/T8 -> #DIV/0! | Z10: =W8/R8 -> #DIV/0! | AA10: =MAX(0, (P8 * G8) - E8) -> 0 | AB10: =MAX(0, (Q8 * G8) - F8) -> 0 | AC10: =R8-K8-J8 -> -76.333333

Sheet summary_by_categories
A1: Categoría | B1: Tipo | C1: user | D1: compartido | E1: período | F1: monto
A2: =IFERROR(__xludf.DUMMYFUNCTION("LET( datos_gastos, expenses_by_installments!A2:N23671, cat_maestra, 'expenses-categories'!B2:D23671, col_cat_gasto, INDEX(datos_gastos,,4), col_compartido_gasto, INDEX(datos_gastos,,10), col_user_gasto, INDEX(datos_gastos,,11), col"&"_periodo_gasto, INDEX(datos_gastos,,14), col_monto_gasto, INDEX(datos_gastos,,12), universo, UNIQUE(FILTER(HSTACK(col_cat_gasto, col_periodo_gasto, col_user_gasto, col_compartido_gasto), (col_cat_gasto<>""""))), resumen, BYROW(universo, LAMBDA"&"(fila, LET( cat_nom, INDEX(fila, 1, 1), p_orig, INDEX(fila, 1, 2), usuario, INDEX(fila, 1, 3), comp, INDEX(fila, 1, 4), periodo_iso, RIGHT(p_orig, 4) & ""-"" & LEFT(p_orig, 2), "&" tipo, XLOOKUP(cat_nom, INDEX(cat_maestra,,1), INDEX(cat_maestra,,3), ""Gasto""), monto, SUMIFS(col_monto_gasto, col_cat_gasto, cat_nom, col_periodo_gasto, p_orig, col_user_gasto, usuario, col_compartido_gasto, comp), HSTACK(cat_"&"nom, tipo, usuario, comp, periodo_iso, monto) ) )), SORT(FILTER(resumen, (INDEX(resumen,,6)>0)), 5, TRUE) )"),"servicios") -> servicios | B2: =IFERROR(__xludf.DUMMYFUNCTION("""COMPUTED_VALUE"""),"Gasto") -> Gasto | C2: =IFERROR(__xludf.DUMMYFUNCTION("""COMPUTED_VALUE"""),"user-b") -> user-b | D2: =IFERROR(__xludf.DUMMYFUNCTION("""COMPUTED_VALUE"""),"Si") -> Si | E2: =IFERROR(__xludf.DUMMYFUNCTION("""COMPUTED_VALUE"""),"2024-06") -> 2024-06 | F2: =IFERROR(__xludf.DUMMYFUNCTION("""COMPUTED_VALUE"""),231.0) -> 231
A3: =IFERROR(__xludf.DUMMYFUNCTION("""COMPUTED_VALUE"""),"salario") -> salario | B3: =IFERROR(__xludf.DUMMYFUNCTION("""COMPUTED_VALUE"""),"Ingreso") -> Ingreso | C3: =IFERROR(__xludf.DUMMYFUNCTION("""COMPUTED_VALUE"""),"user-b") -> user-b | D3: =IFERROR(__xludf.DUMMYFUNCTION("""COMPUTED_VALUE"""),"Si") -> Si | E3: =IFERROR(__xludf.DUMMYFUNCTION("""COMPUTED_VALUE"""),"2024-06") -> 2024-06 | F3: =IFERROR(__xludf.DUMMYFUNCTION("""COMPUTED_VALUE"""),5175.0) -> 5175
A4: =IFERROR(__xludf.DUMMYFUNCTION("""COMPUTED_VALUE"""),"super") -> super | B4: =IFERROR(__xludf.DUMMYFUNCTION("""COMPUTED_VALUE"""),"Gasto") -> Gasto | C4: =IFERROR(__xludf.DUMMYFUNCTION("""COMPUTED_VALUE"""),"user-b") -> user-b | D4: =IFERROR(__xludf.DUMMYFUNCTION("""COMPUTED_VALUE"""),"Si") -> Si | E4: =IFERROR(__xludf.DUMMYFUNCTION("""COMPUTED_VALUE"""),"2024-06") -> 2024-06 | F4: =IFERROR(__xludf.DUMMYFUNCTION("""COMPUTED_VALUE"""),117.51824817518248) -> 117.51825
A5: =IFERROR(__xludf.DUMMYFUNCTION("""COMPUTED_VALUE"""),"salidas") -> salidas | B5: =IFERROR(__xludf.DUMMYFUNCTION("""COMPUTED_VALUE"""),"Gasto") -> Gasto | C5: =IFERROR(__xludf.DUMMYFUNCTION("""COMPUTED_VALUE"""),"user-b") -> user-b | D5: =IFERROR(__xludf.DUMMYFUNCTION("""COMPUTED_VALUE"""),"Si") -> Si | E5: =IFERROR(__xludf.DUMMYFUNCTION("""COMPUTED_VALUE"""),"2024-06") -> 2024-06 | F5: =IFERROR(__xludf.DUMMYFUNCTION("""COMPUTED_VALUE"""),258.3941605839416) -> 258.39416
A6: =IFERROR(__xludf.DUMMYFUNCTION("""COMPUTED_VALUE"""),"delivery") -> delivery | B6: =IFERROR(__xludf.DUMMYFUNCTION("""COMPUTED_VALUE"""),"Gasto") -> Gasto | C6: =IFERROR(__xludf.DUMMYFUNCTION("""COMPUTED_VALUE"""),"user-b") -> user-b | D6: =IFERROR(__xludf.DUMMYFUNCTION("""COMPUTED_VALUE"""),"Si") -> Si | E6: =IFERROR(__xludf.DUMMYFUNCTION("""COMPUTED_VALUE"""),"2024-06") -> 2024-06 | F6: =IFERROR(__xludf.DUMMYFUNCTION("""COMPUTED_VALUE"""),125.91240875912409) -> 125.91241
A7: =IFERROR(__xludf.DUMMYFUNCTION("""COMPUTED_VALUE"""),"otros") -> otros | B7: =IFERROR(__xludf.DUMMYFUNCTION("""COMPUTED_VALUE"""),"Gasto") -> Gasto | C7: =IFERROR(__xludf.DUMMYFUNCTION("""COMPUTED_VALUE"""),"user-b") -> user-b | D7: =IFERROR(__xludf.DUMMYFUNCTION("""COMPUTED_VALUE"""),"No") -> No | E7: =IFERROR(__xludf.DUMMYFUNCTION("""COMPUTED_VALUE"""),"2024-06") -> 2024-06 | F7: =IFERROR(__xludf.DUMMYFUNCTION("""COMPUTED_VALUE"""),209.03284671532847) -> 209.03285
A8: =IFERROR(__xludf.DUMMYFUNCTION("""COMPUTED_VALUE"""),"auto") -> auto | B8: =IFERROR(__xludf.DUMMYFUNCTION("""COMPUTED_VALUE"""),"Gasto") -> Gasto | C8: =IFERROR(__xludf.DUMMYFUNCTION("""COMPUTED_VALUE"""),"user-b") -> user-b | D8: =IFERROR(__xludf.DUMMYFUNCTION("""COMPUTED_VALUE"""),"Si") -> Si | E8: =IFERROR(__xludf.DUMMYFUNCTION("""COMPUTED_VALUE"""),"2024-06") -> 2024-06 | F8: =IFERROR(__xludf.DUMMYFUNCTION("""COMPUTED_VALUE"""),46.715328467153284) -> 46.715328
A9: =IFERROR(__xludf.DUMMYFUNCTION("""COMPUTED_VALUE"""),"nafta") -> nafta | B9: =IFERROR(__xludf.DUMMYFUNCTION("""COMPUTED_VALUE"""),"Gasto") -> Gasto | C9: =IFERROR(__xludf.DUMMYFUNCTION("""COMPUTED_VALUE"""),"user-b") -> user-b | D9: =IFERROR(__xludf.DUMMYFUNCTION("""COMPUTED_VALUE"""),"Si") -> Si | E9: =IFERROR(__xludf.DUMMYFUNCTION("""COMPUTED_VALUE"""),"2024-06") -> 2024-06 | F9: =IFERROR(__xludf.DUMMYFUNCTION("""COMPUTED_VALUE"""),16.05839416058394) -> 16.058394
A10: =IFERROR(__xludf.DUMMYFUNCTION("""COMPUTED_VALUE"""),"otros") -> otros | B10: =IFERROR(__xludf.DUMMYFUNCTION("""COMPUTED_VALUE"""),"Gasto") -> Gasto | C10: =IFERROR(__xludf.DUMMYFUNCTION("""COMPUTED_VALUE"""),"user-b") -> user-b | D10: =IFERROR(__xludf.DUMMYFUNCTION("""COMPUTED_VALUE"""),"No") -> No | E10: =IFERROR(__xludf.DUMMYFUNCTION("""COMPUTED_VALUE"""),"2024-07") -> 2024-07 | F10: =IFERROR(__xludf.DUMMYFUNCTION("""COMPUTED_VALUE"""),80.94615384615383) -> 80.946154
A11: =IFERROR(__xludf.DUMMYFUNCTION("""COMPUTED_VALUE"""),"super") -> super | B11: =IFERROR(__xludf.DUMMYFUNCTION("""COMPUTED_VALUE"""),"Gasto") -> Gasto | C11: =IFERROR(__xludf.DUMMYFUNCTION("""COMPUTED_VALUE"""),"user-b") -> user-b | D11: =IFERROR(__xludf.DUMMYFUNCTION("""COMPUTED_VALUE"""),"Si") -> Si | E11: =IFERROR(__xludf.DUMMYFUNCTION("""COMPUTED_VALUE"""),"2024-07") -> 2024-07 | F11: =IFERROR(__xludf.DUMMYFUNCTION("""COMPUTED_VALUE"""),212.66153846153847) -> 212.66154
A12: =IFERROR(__xludf.DUMMYFUNCTION("""COMPUTED_VALUE"""),"servicios") -> servicios | B12: =IFERROR(__xludf.DUMMYFUNCTION("""COMPUTED_VALUE"""),"Gasto") -> Gasto | C12: =IFERROR(__xludf.DUMMYFUNCTION("""COMPUTED_VALUE"""),"user-b") -> user-b | D12: =IFERROR(__xludf.DUMMYFUNCTION("""COMPUTED_VALUE"""),"Si") -> Si | E12: =IFERROR(__xludf.DUMMYFUNCTION("""COMPUTED_VALUE"""),"2024-07") -> 2024-07 | F12: =IFERROR(__xludf.DUMMYFUNCTION("""COMPUTED_VALUE"""),244.0) -> 244
A13: =IFERROR(__xludf.DUMMYFUNCTION("""COMPUTED_VALUE"""),"salario") -> salario | B13: =IFERROR(__xludf.DUMMYFUNCTION("""COMPUTED_VALUE"""),"Ingreso") -> Ingreso | C13: =IFERROR(__xludf.DUMMYFUNCTION("""COMPUTED_VALUE"""),"user-b") -> user-b | D13: =IFERROR(__xludf.DUMMYFUNCTION("""COMPUTED_VALUE"""),"Si") -> Si | E13: =IFERROR(__xludf.DUMMYFUNCTION("""COMPUTED_VALUE"""),"2024-07") -> 2024-07 | F13: =IFERROR(__xludf.DUMMYFUNCTION("""COMPUTED_VALUE"""),3750.0) -> 3750
A14: =IFERROR(__xludf.DUMMYFUNCTION("""COMPUTED_VALUE"""),"salidas") -> salidas | B14: =IFERROR(__xludf.DUMMYFUNCTION("""COMPUTED_VALUE"""),"Gasto") -> Gasto | C14: =IFERROR(__xludf.DUMMYFUNCTION("""COMPUTED_VALUE"""),"user-b") -> user-b | D14: =IFERROR(__xludf.DUMMYFUNCTION("""COMPUTED_VALUE"""),"Si") -> Si | E14: =IFERROR(__xludf.DUMMYFUNCTION("""COMPUTED_VALUE"""),"2024-07") -> 2024-07 | F14: =IFERROR(__xludf.DUMMYFUNCTION("""COMPUTED_VALUE"""),185.19230769230768) -> 185.19231
A15: =IFERROR(__xludf.DUMMYFUNCTION("""COMPUTED_VALUE"""),"delivery") -> delivery | B15: =IFERROR(__xludf.DUMMYFUNCTION("""COMPUTED_VALUE"""),"Gasto") -> Gasto | C15: =IFERROR(__xludf.DUMMYFUNCTION("""COMPUTED_VALUE"""),"user-b") -> user-b | D15: =IFERROR(__xludf.DUMMYFUNCTION("""COMPUTED_VALUE"""),"Si") -> Si | E15: =IFERROR(__xludf.DUMMYFUNCTION("""COMPUTED_VALUE"""),"2024-07") -> 2024-07 | F15: =IFERROR(__xludf.DUMMYFUNCTION("""COMPUTED_VALUE"""),172.23076923076923) -> 172.23077
A16: =IFERROR(__xludf.DUMMYFUNCTION("""COMPUTED_VALUE"""),"nafta") -> nafta | B16: =IFERROR(__xludf.DUMMYFUNCTION("""COMPUTED_VALUE"""),"Gasto") -> Gasto | C16: =IFERROR(__xludf.DUMMYFUNCTION("""COMPUTED_VALUE"""),"user-b") -> user-b | D16: =IFERROR(__xludf.DUMMYFUNCTION("""COMPUTED_VALUE"""),"Si") -> Si | E16: =IFERROR(__xludf.DUMMYFUNCTION("""COMPUTED_VALUE"""),"2024-07") -> 2024-07 | F16: =IFERROR(__xludf.DUMMYFUNCTION("""COMPUTED_VALUE"""),17.115384615384617) -> 17.115385
A17: =IFERROR(__xludf.DUMMYFUNCTION("""COMPUTED_VALUE"""),"auto") -> auto | B17: =IFERROR(__xludf.DUMMYFUNCTION("""COMPUTED_VALUE"""),"Gasto") -> Gasto | C17: =IFERROR(__xludf.DUMMYFUNCTION("""COMPUTED_VALUE"""),"user-b") -> user-b | D17: =IFERROR(__xludf.DUMMYFUNCTION("""COMPUTED_VALUE"""),"Si") -> Si | E17: =IFERROR(__xludf.DUMMYFUNCTION("""COMPUTED_VALUE"""),"2024-07") -> 2024-07 | F17: =IFERROR(__xludf.DUMMYFUNCTION("""COMPUTED_VALUE"""),135.96153846153845) -> 135.96154
A18: =IFERROR(__xludf.DUMMYFUNCTION("""COMPUTED_VALUE"""),"otros") -> otros | B18: =IFERROR(__xludf.DUMMYFUNCTION("""COMPUTED_VALUE"""),"Gasto") -> Gasto | C18: =IFERROR(__xludf.DUMMYFUNCTION("""COMPUTED_VALUE"""),"user-b") -> user-b | D18: =IFERROR(__xludf.DUMMYFUNCTION("""COMPUTED_VALUE"""),"No") -> No | E18: =IFERROR(__xludf.DUMMYFUNCTION("""COMPUTED_VALUE"""),"2024-08") -> 2024-08 | F18: =IFERROR(__xludf.DUMMYFUNCTION("""COMPUTED_VALUE"""),66.34008097165992) -> 66.340081
A19: =IFERROR(__xludf.DUMMYFUNCTION("""COMPUTED_VALUE"""),"super") -> super | B19: =IFERROR(__xludf.DUMMYFUNCTION("""COMPUTED_VALUE"""),"Gasto") -> Gasto | C19: =IFERROR(__xludf.DUMMYFUNCTION("""COMPUTED_VALUE"""),"user-b") -> user-b | D19: =IFERROR(__xludf.DUMMYFUNCTION("""COMPUTED_VALUE"""),"Si") -> Si | E19: =IFERROR(__xludf.DUMMYFUNCTION("""COMPUTED_VALUE"""),"2024-08") -> 2024-08 | F19: =IFERROR(__xludf.DUMMYFUNCTION("""COMPUTED_VALUE"""),65.31174089068826) -> 65.311741
A20: =IFERROR(__xludf.DUMMYFUNCTION("""COMPUTED_VALUE"""),"salidas") -> salidas | B20: =IFERROR(__xludf.DUMMYFUNCTION("""COMPUTED_VALUE"""),"Gasto") -> Gasto | C20: =IFERROR(__xludf.DUMMYFUNCTION("""COMPUTED_VALUE"""),"user-b") -> user-b | D20: =IFERROR(__xludf.DUMMYFUNCTION("""COMPUTED_VALUE"""),"Si") -> Si | E20: =IFERROR(__xludf.DUMMYFUNCTION("""COMPUTED_VALUE"""),"2024-08") -> 2024-08 | F20: =IFERROR(__xludf.DUMMYFUNCTION("""COMPUTED_VALUE"""),54.04858299595141) -> 54.048583
A21: =IFERROR(__xludf.DUMMYFUNCTION("""COMPUTED_VALUE"""),"auto") -> auto | B21: =IFERROR(__xludf.DUMMYFUNCTION("""COMPUTED_VALUE"""),"Gasto") -> Gasto | C21: =IFERROR(__xludf.DUMMYFUNCTION("""COMPUTED_VALUE"""),"user-b") -> user-b | D21: =IFERROR(__xludf.DUMMYFUNCTION("""COMPUTED_VALUE"""),"Si") -> Si | E21: =IFERROR(__xludf.DUMMYFUNCTION("""COMPUTED_VALUE"""),"2024-08") -> 2024-08 | F21: =IFERROR(__xludf.DUMMYFUNCTION("""COMPUTED_VALUE"""),20.850202429149796) -> 20.850202
A22: =IFERROR(__xludf.DUMMYFUNCTION("""COMPUTED_VALUE"""),"otros") -> otros | B22: =IFERROR(__xludf.DUMMYFUNCTION("""COMPUTED_VALUE"""),"Gasto") -> Gasto | C22: =IFERROR(__xludf.DUMMYFUNCTION("""COMPUTED_VALUE"""),"user-b") -> user-b | D22: =IFERROR(__xludf.DUMMYFUNCTION("""COMPUTED_VALUE"""),"No") -> No | E22: =IFERROR(__xludf.DUMMYFUNCTION("""COMPUTED_VALUE"""),"2024-09") -> 2024-09 | F22: =IFERROR(__xludf.DUMMYFUNCTION("""COMPUTED_VALUE"""),45.123966942148755) -> 45.123967
A23: =IFERROR(__xludf.DUMMYFUNCTION("""COMPUTED_VALUE"""),"salidas") -> salidas | B23: =IFERROR(__xludf.DUMMYFUNCTION("""COMPUTED_VALUE"""),"Gasto") -> Gasto | C23: =IFERROR(__xludf.DUMMYFUNCTION("""COMPUTED_VALUE"""),"user-b") -> user-b | D23: =IFERROR(__xludf.DUMMYFUNCTION("""COMPUTED_VALUE"""),"Si") -> Si | E23: =IFERROR(__xludf.DUMMYFUNCTION("""COMPUTED_VALUE"""),"2024-09") -> 2024-09 | F23: =IFERROR(__xludf.DUMMYFUNCTION("""COMPUTED_VALUE"""),49.65289256198348) -> 49.652893
A24: =IFERROR(__xludf.DUMMYFUNCTION("""COMPUTED_VALUE"""),"super") -> super | B24: =IFERROR(__xludf.DUMMYFUNCTION("""COMPUTED_VALUE"""),"Gasto") -> Gasto | C24: =IFERROR(__xludf.DUMMYFUNCTION("""COMPUTED_VALUE"""),"user-b") -> user-b | D24: =IFERROR(__xludf.DUMMYFUNCTION("""COMPUTED_VALUE"""),"Si") -> Si | E24: =IFERROR(__xludf.DUMMYFUNCTION("""COMPUTED_VALUE"""),"2024-09") -> 2024-09 | F24: =IFERROR(__xludf.DUMMYFUNCTION("""COMPUTED_VALUE"""),45.17355371900827) -> 45.173554
A25: =IFERROR(__xludf.DUMMYFUNCTION("""COMPUTED_VALUE"""),"auto") -> auto | B25: =IFERROR(__xludf.DUMMYFUNCTION("""COMPUTED_VALUE"""),"Gasto") -> Gasto | C25: =IFERROR(__xludf.DUMMYFUNCTION("""COMPUTED_VALUE"""),"user-b") -> user-b | D25: =IFERROR(__xludf.DUMMYFUNCTION("""COMPUTED_VALUE"""),"Si") -> Si | E25: =IFERROR(__xludf.DUMMYFUNCTION("""COMPUTED_VALUE"""),"2024-09") -> 2024-09 | F25: =IFERROR(__xludf.DUMMYFUNCTION("""COMPUTED_VALUE"""),21.28099173553719) -> 21.280992
A26: =IFERROR(__xludf.DUMMYFUNCTION("""COMPUTED_VALUE"""),"otros") -> otros | B26: =IFERROR(__xludf.DUMMYFUNCTION("""COMPUTED_VALUE"""),"Gasto") -> Gasto | C26: =IFERROR(__xludf.DUMMYFUNCTION("""COMPUTED_VALUE"""),"user-b") -> user-b | D26: =IFERROR(__xludf.DUMMYFUNCTION("""COMPUTED_VALUE"""),"No") -> No | E26: =IFERROR(__xludf.DUMMYFUNCTION("""COMPUTED_VALUE"""),"2024-10") -> 2024-10 | F26: =IFERROR(__xludf.DUMMYFUNCTION("""COMPUTED_VALUE"""),47.89473684210526) -> 47.894737
A27: =IFERROR(__xludf.DUMMYFUNCTION("""COMPUTED_VALUE"""),"auto") -> auto | B27: =IFERROR(__xludf.DUMMYFUNCTION("""COMPUTED_VALUE"""),"Gasto") -> Gasto | C27: =IFERROR(__xludf.DUMMYFUNCTION("""COMPUTED_VALUE"""),"user-b") -> user-b | D27: =IFERROR(__xludf.DUMMYFUNCTION("""COMPUTED_VALUE"""),"Si") -> Si | E27: =IFERROR(__xludf.DUMMYFUNCTION("""COMPUTED_VALUE"""),"2024-10") -> 2024-10 | F27: =IFERROR(__xludf.DUMMYFUNCTION("""COMPUTED_VALUE"""),22.587719298245613) -> 22.587719
A28: =IFERROR(__xludf.DUMMYFUNCTION("""COMPUTED_VALUE"""),"salidas") -> salidas | B28: =IFERROR(__xludf.DUMMYFUNCTION("""COMPUTED_VALUE"""),"Gasto") -> Gasto | C28: =IFERROR(__xludf.DUMMYFUNCTION("""COMPUTED_VALUE"""),"user-b") -> user-b | D28: =IFERROR(__xludf.DUMMYFUNCTION("""COMPUTED_VALUE"""),"Si") -> Si | E28: =IFERROR(__xludf.DUMMYFUNCTION("""COMPUTED_VALUE"""),"2024-10") -> 2024-10 | F28: =IFERROR(__xludf.DUMMYFUNCTION("""COMPUTED_VALUE"""),5.850877192982456) -> 5.8508772
A29: =IFERROR(__xludf.DUMMYFUNCTION("""COMPUTED_VALUE"""),"otros") -> otros | B29: =IFERROR(__xludf.DUMMYFUNCTION("""COMPUTED_VALUE"""),"Gasto") -> Gasto | C29: =IFERROR(__xludf.DUMMYFUNCTION("""COMPUTED_VALUE"""),"user-b") -> user-b | D29: =IFERROR(__xludf.DUMMYFUNCTION("""COMPUTED_VALUE"""),"No") -> No | E29: =IFERROR(__xludf.DUMMYFUNCTION("""COMPUTED_VALUE"""),"2024-11") -> 2024-11 | F29: =IFERROR(__xludf.DUMMYFUNCTION("""COMPUTED_VALUE"""),50.79069767441861) -> 50.790698
A30: =IFERROR(__xludf.DUMMYFUNCTION("""COMPUTED_VALUE"""),"auto") -> auto | B30: =IFERROR(__xludf.DUMMYFUNCTION("""COMPUTED_VALUE"""),"Gasto") -> Gasto | C30: =IFERROR(__xludf.DUMMYFUNCTION("""COMPUTED_VALUE"""),"user-b") -> user-b | D30: =IFERROR(__xludf.DUMMYFUNCTION("""COMPUTED_VALUE"""),"Si") -> Si | E30: =IFERROR(__xludf.DUMMYFUNCTION("""COMPUTED_VALUE"""),"2024-11") -> 2024-11 | F30: =IFERROR(__xludf.DUMMYFUNCTION("""COMPUTED_VALUE"""),23.953488372093023) -> 23.953488
A31: =IFERROR(__xludf.DUMMYFUNCTION("""COMPUTED_VALUE"""),"otros") -> otros | B31: =IFERROR(__xludf.DUMMYFUNCTION("""COMPUTED_VALUE"""),"Gasto") -> Gasto | C31: =IFERROR(__xludf.DUMMYFUNCTION("""COMPUTED_VALUE"""),"user-b") -> user-b | D31: =IFERROR(__xludf.DUMMYFUNCTION("""COMPUTED_VALUE"""),"No") -> No | E31: =IFERROR(__xludf.DUMMYFUNCTION("""COMPUTED_VALUE"""),"2024-12") -> 2024-12 | F31: =IFERROR(__xludf.DUMMYFUNCTION("""COMPUTED_VALUE"""),32.98695652173914) -> 32.986957
A32: =IFERROR(__xludf.DUMMYFUNCTION("""COMPUTED_VALUE"""),"auto") -> auto | B32: =IFERROR(__xludf.DUMMYFUNCTION("""COMPUTED_VALUE"""),"Gasto") -> Gasto | C32: =IFERROR(__xludf.DUMMYFUNCTION("""COMPUTED_VALUE"""),"user-b") -> user-b | D32: =IFERROR(__xludf.DUMMYFUNCTION("""COMPUTED_VALUE"""),"Si") -> Si | E32: =IFERROR(__xludf.DUMMYFUNCTION("""COMPUTED_VALUE"""),"2024-12") -> 2024-12 | F32: =IFERROR(__xludf.DUMMYFUNCTION("""COMPUTED_VALUE"""),22.391304347826086) -> 22.391304

Sheet expenses
A1: Id | B1: Período | C1: Categoría | D1: Monto | E1: Cuotas | F1: Moneda | G1: Comentario | H1: Ingreso/Egreso | I1: Compartido | J1: usuario
A2: c88c1ddc-0a86-11f1-af1e-325096b39f47 | B2: 45444 | C2: servicios | D2: 231 | E2: 1 | F2: USD | H2: Egreso | I2: Si | J2: user-b
A3: 00349dd4-0ab1-11f1-81b6-325096b39f47 | B3: 45444 | C3: salario | D3: 1500 | E3: 1 | F3: USD | H3: Ingreso | I3: Si | J3: user-b
A4: 5c80570a | B4: 45451 | C4: super | D4: 6000 | E4: 1 | F4: ARS | H4: Egreso | I4: Si | J4: user-b
A5: e29fba8f | B5: 45451 | C5: salidas | D5: 42000 | E5: 1 | F5: ARS | H5: Egreso | I5: Si | J5: user-b
A6: ba548b7a | B6: 45452 | C6: super | D6: 62000 | E6: 1 | F6: ARS | H6: Egreso | I6: Si | J6: user-b
A7: 84763a1b | B7: 45452 | C7: delivery | D7: 14000 | E7: 1 | F7: ARS | H7: Egreso | I7: Si | J7: user-b
A8: 598b7297 | B8: 45453 | C8: delivery | D8: 9500 | E8: 1 | F8: ARS | H8: Egreso | I8: Si | J8: user-b
A9: 2ca822bc | B9: 45454 | C9: delivery | D9: 12000 | E9: 1 | F9: ARS | H9: Egreso | I9: Si | J9: user-b
A10: 1550232e | B10: 45454 | C10: salidas | D10: 36000 | E10: 1 | F10: ARS | H10: Egreso | I10: Si | J10: user-b
A11: c17d2e81 | B11: 45455 | C11: super | D11: 2000 | E11: 1 | F11: ARS | H11: Egreso | I11: Si | J11: user-b
A12: 0064096d | B12: 45456 | C12: otros | D12: 45990 | E12: 3 | F12: ARS | G12: Teclado | H12: Egreso | I12: No | J12: user-b
A13: 3d675d52 | B13: 45456 | C13: delivery | D13: 10000 | E13: 1 | F13: ARS | H13: Egreso | I13: Si | J13: user-b
A14: 2242ddfb | B14: 45457 | C14: delivery | D14: 26000 | E14: 1 | F14: ARS | H14: Egreso | I14: Si | J14: user-b
A15: d59172c2 | B15: 45458 | C15: delivery | D15: 36000 | E15: 1 | F15: ARS | H15: Egreso | I15: Si | J15: user-b
A16: c21ccf8d | B16: 45458 | C16: super | D16: 8000 | E16: 1 | F16: ARS | H16: Egreso | I16: Si | J16: user-b
A17: f7a63002 | B17: 45458 | C17: otros | D17: 4000 | E17: 1 | F17: ARS | H17: Egreso | I17: No | J17: user-b
A18: 625bdd9f | B18: 45459 | C18: otros | D18: 13 | E18: 1 | F18: USD | G18: Android games | H18: Egreso | I18: No | J18: user-b
A19: 018508b9 | B19: 45459 | C19: salidas | D19: 19000 | E19: 1 | F19: ARS | G19: Cine | H19: Egreso | I19: Si | J19: user-b
A20: 0678954a | B20: 45459 | C20: super | D20: 12000 | E20: 3 | F20: ARS | H20: Egreso | I20: Si | J20: user-b
A21: 401cbf11 | B21: 45460 | C21: super | D21: 15990 | E21: 3 | F21: ARS | G21: Café | H21: Egreso | I21: Si | J21: user-b
A22: 940e81b5 | B22: 45460 | C22: delivery | D22: 22000 | E22: 1 | F22: ARS | H22: Egreso | I22: Si | J22: user-b
A23: d4ef954e | B23: 45460 | C23: super | D23: 15000 | E23: 1 | F23: ARS | H23: Egreso | I23: Si | J23: user-b
A24: fdc86f90 | B24: 45461 | C24: delivery | D24: 10000 | E24: 1 | F24: ARS | H24: Egreso | I24: Si | J24: user-b
A25: a3ee2198 | B25: 45462 | C25: super | D25: 32010 | E25: 3 | F25: ARS | H25: Egreso | I25: Si | J25: user-b
A26: 708768c6 | B26: 45463 | C26: super | D26: 18000 | E26: 3 | F26: ARS | G26: Farmacia | H26: Egreso | I26: Si | J26: user-b
A27: 598090be | B27: 45463 | C27: otros | D27: 99990 | E27: 6 | F27: ARS | G27: Ropa y regalo | H27: Egreso | I27: No | J27: user-b
A28: 0fb61cb0 | B28: 45463 | C28: super | D28: 32000 | E28: 1 | F28: ARS | H28: Egreso | I28: Si | J28: user-b
A29: 03ed6348 | B29: 45464 | C29: auto | D29: 64000 | E29: 1 | F29: ARS | G29: Seguro | H29: Egreso | I29: Si | J29: user-b
A30: 9512b155 | B30: 45464 | C30: salidas | D30: 46000 | E30: 1 | F30: ARS | H30: Egreso | I30: Si | J30: user-b
A31: 9d6c1d28 | B31: 45465 | C31: otros | D31: 150 | E31: 1 | F31: USD | G31: joysticks | H31: Egreso | I31: No | J31: user-b
A32: 46d5ddb2 | B32: 45465 | C32: otros | D32: 11 | E32: 1 | F32: USD | G32: Steam | H32: Egreso | I32: No | J32: user-b
A33: a75d03e8 | B33: 45465 | C33: delivery | D33: 11000 | E33: 1 | F33: ARS | H33: Egreso | I33: Si | J33: user-b
A34: 5dc0634c | B34: 45467 | C34: nafta | D34: 22000 | E34: 1 | F34: ARS | H34: Egreso | I34: Si | J34: user-b
A35: 55adfa1b | B35: 45468 | C35: otros | D35: 36000 | E35: 3 | F35: ARS | G35: micro sd | H35: Egreso | I35: No | J35: user-b
A36: 1c07f07c | B36: 45469 | C36: delivery | D36: 8000 | E36: 1 | F36: ARS | H36: Egreso | I36: Si | J36: user-b
A37: f4f9ecd1 | B37: 45470 | C37: salidas | D37: 70000 | E37: 1 | F37: ARS | H37: Egreso | I37: Si | J37: user-b
A38: ca631e01 | B38: 45471 | C38: delivery | D38: 14000 | E38: 1 | F38: ARS | H38: Egreso | I38: Si | J38: user-b
A39: 7c6577c4 | B39: 45472 | C39: salidas | D39: 45000 | E39: 1 | F39: ARS | G39: Almuerzo floa | H39: Egreso | I39: Si | J39: user-b
A40: 3308ceed | B40: 45472 | C40: salidas | D40: 40000 | E40: 1 | F40: ARS | H40: Egreso | I40: Si | J40: user-b
...

Sheet expenses_by_installments
A1: ID | B1: PERÍODO | C1: PERIODO_ORIGEN | D1: CATEGORÍA | E1: MONTO CUOTA | F1: CUOTAS | G1: MONEDA | H1: COMENTARIO | I1: INGRESO/EGRESO | J1: COMPARTIDO | K1: USUARIO | L1: USD (MES CUOTA) | M1: USD (ORIGEN) | N1: MES-AÑO
A2: c88c1ddc-0a86-11f1-af1e-325096b39f47 | B2: 45444 | C2: 45444 | D2: servicios | E2: 231 | F2: 1 | G2: USD | I2: Egreso | J2: Si | K2: user-b | L2: 231 | M2: 231 | N2: 06-2024
A3: 00349dd4-0ab1-11f1-81b6-325096b39f47 | B3: 45444 | C3: 45444 | D3: salario | E3: 1500 | F3: 1 | G3: USD | I3: Ingreso | J3: Si | K3: user-b | L3: 5175 | M3: 5175 | N3: 06-2024
A4: 5c80570a | B4: 45451 | C4: 45451 | D4: super | E4: 6000 | F4: 1 | G4: ARS | I4: Egreso | J4: Si | K4: user-b | L4: 4.379562 | M4: 4.379562 | N4: 06-2024
A5: e29fba8f | B5: 45451 | C5: 45451 | D5: salidas | E5: 42000 | F5: 1 | G5: ARS | I5: Egreso | J5: Si | K5: user-b | L5: 30.656934 | M5: 30.656934 | N5: 06-2024
A6: ba548b7a | B6: 45452 | C6: 45452 | D6: super | E6: 62000 | F6: 1 | G6: ARS | I6: Egreso | J6: Si | K6: user-b | L6: 45.255474 | M6: 45.255474 | N6: 06-2024
A7: 84763a1b | B7: 45452 | C7: 45452 | D7: delivery | E7: 14000 | F7: 1 | G7: ARS | I7: Egreso | J7: Si | K7: user-b | L7: 10.218978 | M7: 10.218978 | N7: 06-2024
A8: 598b7297 | B8: 45453 | C8: 45453 | D8: delivery | E8: 9500 | F8: 1 | G8: ARS | I8: Egreso | J8: Si | K8: user-b | L8: 6.9343066 | M8: 6.9343066 | N8: 06-2024
A9: 2ca822bc | B9: 45454 | C9: 45454 | D9: delivery | E9: 12000 | F9: 1 | G9: ARS | I9: Egreso | J9: Si | K9: user-b | L9: 8.7591241 | M9: 8.7591241 | N9: 06-2024
A10: 1550232e | B10: 45454 | C10: 45454 | D10: salidas | E10: 36000 | F10: 1 | G10: ARS | I10: Egreso | J10: Si | K10: user-b | L10: 26.277372 | M10: 26.277372 | N10: 06-2024
A11: c17d2e81 | B11: 45455 | C11: 45455 | D11: super | E11: 2000 | F11: 1 | G11: ARS | I11: Egreso | J11: Si | K11: user-b | L11: 1.459854 | M11: 1.459854 | N11: 06-2024
A12: 0064096d | B12: 45456 | C12: 45456 | D12: otros | E12: 15330 | F12: 3 | G12: ARS | H12: Teclado | I12: Egreso | J12: No | K12: user-b | L12: 11.189781 | M12: 11.189781 | N12: 06-2024
A13: 0064096d | B13: 45486 | C13: 45456 | D13: otros | E13: 15330 | F13: 3 | G13: ARS | H13: Teclado | I13: Egreso | J13: No | K13: user-b | L13: 11.792308 | M13: 11.189781 | N13: 07-2024
A14: 0064096d | B14: 45517 | C14: 45456 | D14: otros | E14: 15330 | F14: 3 | G14: ARS | H14: Teclado | I14: Egreso | J14: No | K14: user-b | L14: 12.412955 | M14: 11.189781 | N14: 08-2024
A15: 3d675d52 | B15: 45456 | C15: 45456 | D15: delivery | E15: 10000 | F15: 1 | G15: ARS | I15: Egreso | J15: Si | K15: user-b | L15: 7.2992701 | M15: 7.2992701 | N15: 06-2024
A16: 2242ddfb | B16: 45457 | C16: 45457 | D16: delivery | E16: 26000 | F16: 1 | G16: ARS | I16: Egreso | J16: Si | K16: user-b | L16: 18.978102 | M16: 18.978102 | N16: 06-2024
A17: d59172c2 | B17: 45458 | C17: 45458 | D17: delivery | E17: 36000 | F17: 1 | G17: ARS | I17: Egreso | J17: Si | K17: user-b | L17: 26.277372 | M17: 26.277372 | N17: 06-2024
A18: c21ccf8d | B18: 45458 | C18: 45458 | D18: super | E18: 8000 | F18: 1 | G18: ARS | I18: Egreso | J18: Si | K18: user-b | L18: 5.8394161 | M18: 5.8394161 | N18: 06-2024
A19: f7a63002 | B19: 45458 | C19: 45458 | D19: otros | E19: 4000 | F19: 1 | G19: ARS | I19: Egreso | J19: No | K19: user-b | L19: 2.919708 | M19: 2.919708 | N19: 06-2024
A20: 625bdd9f | B20: 45459 | C20: 45459 | D20: otros | E20: 13 | F20: 1 | G20: USD | H20: Android games | I20: Egreso | J20: No | K20: user-b | L20: 13 | M20: 13 | N20: 06-2024
A21: 018508b9 | B21: 45459 | C21: 45459 | D21: salidas | E21: 19000 | F21: 1 | G21: ARS | H21: Cine | I21: Egreso | J21: Si | K21: user-b | L21: 13.868613 | M21: 13.868613 | N21: 06-2024
A22: 0678954a | B22: 45459 | C22: 45459 | D22: super | E22: 4000 | F22: 3 | G22: ARS | I22: Egreso | J22: Si | K22: user-b | L22: 2.919708 | M22: 2.919708 | N22: 06-2024
A23: 0678954a | B23: 45489 | C23: 45459 | D23: super | E23: 4000 | F23: 3 | G23: ARS | I23: Egreso | J23: Si | K23: user-b | L23: 3.0769231 | M23: 2.919708 | N23: 07-2024
A24: 0678954a | B24: 45520 | C24: 45459 | D24: super | E24: 4000 | F24: 3 | G24: ARS | I24: Egreso | J24: Si | K24: user-b | L24: 3.2388664 | M24: 2.919708 | N24: 08-2024
A25: 401cbf11 | B25: 45460 | C25: 45460 | D25: super | E25: 5330 | F25: 3 | G25: ARS | H25: Café | I25: Egreso | J25: Si | K25: user-b | L25: 3.8905109 | M25: 3.8905109 | N25: 06-2024
A26: 401cbf11 | B26: 45490 | C26: 45460 | D26: super | E26: 5330 | F26: 3 | G26: ARS | H26: Café | I26: Egreso | J26: Si | K26: user-b | L26: 4.1 | M26: 3.8905109 | N26: 07-2024
A27: 401cbf11 | B27: 45521 | C27: 45460 | D27: super | E27: 5330 | F27: 3 | G27: ARS | H27: Café | I27: Egreso | J27: Si | K27: user-b | L27: 4.3157895 | M27: 3.8905109 | N27: 08-2024
A28: 940e81b5 | B28: 45460 | C28: 45460 | D28: delivery | E28: 22000 | F28: 1 | G28: ARS | I28: Egreso | J28: Si | K28: user-b | L28: 16.058394 | M28: 16.058394 | N28: 06-2024
A29: d4ef954e | B29: 45460 | C29: 45460 | D29: super | E29: 15000 | F29: 1 | G29: ARS | I29: Egreso | J29: Si | K29: user-b | L29: 10.948905 | M29: 10.948905 | N29: 06-2024
A30: fdc86f90 | B30: 45461 | C30: 45461 | D30: delivery | E30: 10000 | F30: 1 | G30: ARS | I30: Egreso | J30: Si | K30: user-b | L30: 7.2992701 | M30: 7.2992701 | N30: 06-2024
A31: a3ee2198 | B31: 45462 | C31: 45462 | D31: super | E31: 10670 | F31: 3 | G31: ARS | I31: Egreso | J31: Si | K31: user-b | L31: 7.7883212 | M31: 7.7883212 | N31: 06-2024
A32: a3ee2198 | B32: 45492 | C32: 45462 | D32: super | E32: 10670 | F32: 3 | G32: ARS | I32: Egreso | J32: Si | K32: user-b | L32: 8.2076923 | M32: 7.7883212 | N32: 07-2024
A33: a3ee2198 | B33: 45523 | C33: 45462 | D33: super | E33: 10670 | F33: 3 | G33: ARS | I33: Egreso | J33: Si | K33: user-b | L33: 8.6396761 | M33: 7.7883212 | N33: 08-2024
A34: 708768c6 | B34: 45463 | C34: 45463 | D34: super | E34: 6000 | F34: 3 | G34: ARS | H34: Farmacia | I34: Egreso | J34: Si | K34: user-b | L34: 4.379562 | M34: 4.379562 | N34: 06-2024
A35: 708768c6 | B35: 45493 | C35: 45463 | D35: super | E35: 6000 | F35: 3 | G35: ARS | H35: Farmacia | I35: Egreso | J35: Si | K35: user-b | L35: 4.6153846 | M35: 4.379562 | N35: 07-2024
A36: 708768c6 | B36: 45524 | C36: 45463 | D36: super | E36: 6000 | F36: 3 | G36: ARS | H36: Farmacia | I36: Egreso | J36: Si | K36: user-b | L36: 4.8582996 | M36: 4.379562 | N36: 08-2024
A37: 598090be | B37: 45463 | C37: 45463 | D37: otros | E37: 16665 | F37: 6 | G37: ARS | H37: Ropa y regalo | I37: Egreso | J37: No | K37: user-b | L37: 12.164234 | M37: 12.164234 | N37: 06-2024
A38: 598090be | B38: 45493 | C38: 45463 | D38: otros | E38: 16665 | F38: 6 | G38: ARS | H38: Ropa y regalo | I38: Egreso | J38: No | K38: user-b | L38: 12.819231 | M38: 12.164234 | N38: 07-2024
A39: 598090be | B39: 45524 | C39: 45463 | D39: otros | E39: 16665 | F39: 6 | G39: ARS | H39: Ropa y regalo | I39: Egreso | J39: No | K39: user-b | L39: 13.493927 | M39: 12.164234 | N39: 08-2024
A40: 598090be | B40: 45555 | C40: 45463 | D40: otros | E40: 16665 | F40: 6 | G40: ARS | H40: Ropa y regalo | I40: Egreso | J40: No | K40: user-b | L40: 13.772727 | M40: 12.164234 | N40: 09-2024
...

Sheet expenses-categories
A1: id | B1: nombre | C1: emoji | D1: type | E1: usuario
A2: cart | B2: super | C2: 🛒 | D2: Gasto | E2: shared
A3: other | B3: otros | C3: 🧦 | D3: Gasto | E3: shared
A4: car | B4: auto | C4: 🚙 | D4: Gasto | E4: shared
A5: holidays | B5: vacaciones | C5: 🌴 | D5: Gasto | E5: shared
A6: fuel | B6: nafta | C6: ⛽ | D6: Gasto | E6: shared
A7: delivery | B7: delivery | C7: 🍕 | D7: Gasto | E7: shared
A8: manteinance | B8: refaccion | C8: 🔧 | D8: Gasto | E8: shared
A9: taxes | B9: impuestos | C9: 📃 | D9: Gasto | E9: shared
A10: goingout | B10: salidas | C10: 🍷 | D10: Gasto | E10: shared
A11: medic | B11: salud | C11: ⚕️ | D11: Gasto | E11: shared
A12: utilities | B12: servicios | C12: 🏠 | D12: Gasto | E12: shared
... A19: pets | B19: perros | C19: 🐕 | D19: Gasto | E19: shared

Sheet exchange
A1: period | B1: usd | C1: eur
A2: 45383 | B2: 1030 | C2: 0.84
A3: 45413 | B3: 1279 | C3: 0.84
A4: 45444 | B4: 1370 | C4: 0.84
A5: 45474 | B5: 1300 | C5: 0.84
A6: 45505 | B6: 1235 | C6: 0.84
A7: 45536 | B7: 1210 | C7: 0.84
A8: 45566 | B8: 1140 | C8: 0.84
A9: 45597 | B9: 1075 | C9: 0.84
A10: 45627 | B10: 1150 | C10: 0.84
A11: 45658 | B11: 1160 | C11: 0.84
A12: 45689 | B12: 1200 | C12: 0.84
A13: 45717 | B13: 1300 | C13: 0.84
... A30: 46235 | B30: 1510 | C30: 0.88

Sheet habits
A1: day | B1: training | C1: dont-smoke | D1: dont-scroll | E1: user
A2: 46251 | B2: FALSE | C2: FALSE | D2: FALSE | E2: user-b
A3: 46252 | B3: TRUE | C3: TRUE | D3: FALSE | E3: user-b
A4: 46253 | B4: FALSE | C4: FALSE | D4: FALSE | E4: user-b
A5: 46254 | B5: TRUE | C5: TRUE | D5: FALSE | E5: user-b
A6: 46256 | B6: FALSE | C6: TRUE | D6: FALSE | E6: user-b

Sheet habits-categories
A1: id | B1: nombre | C1: emoji | D1: default | E1: user
A2: training | B2: Entrenamiento | C2: 🏋️‍♂️ | D2: FALSE | E2: user-b
A3: dont-smoke | B3: No fumar | C3: 🚭 | D3: TRUE | E3: user-b
A4: dont-scroll | B4: Celu Detox | C4: 📵 | D4: FALSE | E4: user-b
